"""
异常处理和错误边界测试用例
测试覆盖：网络异常、服务不可用、数据格式错误、资源耗尽、超时处理
"""

import pytest
import asyncio
import json
import time
from unittest.mock import Mock, patch, AsyncMock
from concurrent.futures import ThreadPoolExecutor, TimeoutError as FutureTimeoutError
import aiohttp
import requests
from requests.exceptions import ConnectionError, Timeout, RequestException


class TestNetworkErrorHandling:
    """网络异常处理测试"""
    
    @pytest.mark.asyncio
    async def test_connection_timeout_handling(self):
        """测试连接超时处理"""
        async def simulate_slow_service():
            """模拟慢速服务"""
            await asyncio.sleep(2)  # 2秒延迟
            return {"status": "success"}
        
        async def call_service_with_timeout(timeout=1):
            """带超时的服务调用"""
            try:
                result = await asyncio.wait_for(simulate_slow_service(), timeout=timeout)
                return {"success": True, "data": result}
            except asyncio.TimeoutError:
                return {"success": False, "error": "服务调用超时", "error_code": "TIMEOUT"}
            except Exception as e:
                return {"success": False, "error": str(e), "error_code": "UNKNOWN"}
        
        # 测试超时情况
        result = await call_service_with_timeout(timeout=0.5)
        assert not result["success"]
        assert result["error_code"] == "TIMEOUT"
        assert "超时" in result["error"]
    
    @pytest.mark.asyncio
    async def test_connection_refused_handling(self):
        """测试连接拒绝处理"""
        async def call_unavailable_service():
            """调用不可用服务"""
            try:
                async with aiohttp.ClientSession() as session:
                    async with session.get("http://localhost:99999/api/test", timeout=1) as response:
                        return await response.json()
            except aiohttp.ClientConnectorError:
                return {"success": False, "error": "服务不可用", "error_code": "SERVICE_UNAVAILABLE"}
            except asyncio.TimeoutError:
                return {"success": False, "error": "连接超时", "error_code": "TIMEOUT"}
            except Exception as e:
                return {"success": False, "error": str(e), "error_code": "UNKNOWN"}
        
        result = await call_unavailable_service()
        assert not result["success"]
        assert result["error_code"] in ["SERVICE_UNAVAILABLE", "TIMEOUT"]
    
    def test_http_error_status_handling(self):
        """测试HTTP错误状态处理"""
        def handle_http_response(status_code, content):
            """处理HTTP响应"""
            if status_code == 200:
                return {"success": True, "data": json.loads(content)}
            elif status_code == 400:
                return {"success": False, "error": "请求参数错误", "error_code": "BAD_REQUEST"}
            elif status_code == 401:
                return {"success": False, "error": "未授权访问", "error_code": "UNAUTHORIZED"}
            elif status_code == 403:
                return {"success": False, "error": "访问被禁止", "error_code": "FORBIDDEN"}
            elif status_code == 404:
                return {"success": False, "error": "资源未找到", "error_code": "NOT_FOUND"}
            elif status_code == 429:
                return {"success": False, "error": "请求过于频繁", "error_code": "RATE_LIMITED"}
            elif status_code >= 500:
                return {"success": False, "error": "服务器内部错误", "error_code": "SERVER_ERROR"}
            else:
                return {"success": False, "error": f"未知状态码: {status_code}", "error_code": "UNKNOWN"}
        
        # 测试各种HTTP状态码
        test_cases = [
            (200, '{"result": "success"}', True, None),
            (400, '{"error": "bad request"}', False, "BAD_REQUEST"),
            (401, '{"error": "unauthorized"}', False, "UNAUTHORIZED"),
            (404, '{"error": "not found"}', False, "NOT_FOUND"),
            (500, '{"error": "server error"}', False, "SERVER_ERROR"),
        ]
        
        for status_code, content, expected_success, expected_error_code in test_cases:
            result = handle_http_response(status_code, content)
            assert result["success"] == expected_success
            if not expected_success:
                assert result["error_code"] == expected_error_code
    
    @pytest.mark.asyncio
    async def test_retry_mechanism(self):
        """测试重试机制"""
        class RetryableService:
            def __init__(self):
                self.call_count = 0
            
            async def unreliable_call(self):
                """不可靠的服务调用"""
                self.call_count += 1
                if self.call_count < 3:  # 前两次调用失败
                    raise aiohttp.ClientConnectorError(None, OSError("Connection failed"))
                return {"status": "success", "call_count": self.call_count}
        
        async def call_with_retry(service, max_retries=3, delay=0.1):
            """带重试的服务调用"""
            last_error = None
            
            for attempt in range(max_retries + 1):
                try:
                    result = await service.unreliable_call()
                    return {"success": True, "data": result, "attempts": attempt + 1}
                except Exception as e:
                    last_error = e
                    if attempt < max_retries:
                        await asyncio.sleep(delay * (2 ** attempt))  # 指数退避
                    continue
            
            return {
                "success": False,
                "error": str(last_error),
                "error_code": "MAX_RETRIES_EXCEEDED",
                "attempts": max_retries + 1
            }
        
        # 测试重试成功
        service = RetryableService()
        result = await call_with_retry(service, max_retries=3)
        
        assert result["success"]
        assert result["attempts"] == 3  # 第三次成功
        assert result["data"]["call_count"] == 3


class TestDataValidationErrorHandling:
    """数据验证错误处理测试"""
    
    def test_json_parsing_errors(self):
        """测试JSON解析错误处理"""
        def safe_json_parse(json_string):
            """安全的JSON解析"""
            try:
                return {"success": True, "data": json.loads(json_string)}
            except json.JSONDecodeError as e:
                return {
                    "success": False,
                    "error": f"JSON解析错误: {str(e)}",
                    "error_code": "INVALID_JSON",
                    "line": e.lineno,
                    "column": e.colno
                }
            except Exception as e:
                return {
                    "success": False,
                    "error": f"未知错误: {str(e)}",
                    "error_code": "UNKNOWN"
                }
        
        # 测试有效JSON
        valid_json = '{"name": "test", "value": 123}'
        result = safe_json_parse(valid_json)
        assert result["success"]
        assert result["data"]["name"] == "test"
        
        # 测试无效JSON
        invalid_jsons = [
            '{"name": "test", "value":}',  # 缺少值
            '{"name": "test" "value": 123}',  # 缺少逗号
            '{name: "test"}',  # 键未加引号
            '{"name": "test", "value": 123,}',  # 尾随逗号
        ]
        
        for invalid_json in invalid_jsons:
            result = safe_json_parse(invalid_json)
            assert not result["success"]
            assert result["error_code"] == "INVALID_JSON"
            assert "line" in result
    
    def test_data_type_validation(self):
        """测试数据类型验证"""
        def validate_user_data(data):
            """验证用户数据"""
            errors = []
            
            # 检查必需字段
            required_fields = ["user_id", "username", "email", "age"]
            for field in required_fields:
                if field not in data:
                    errors.append(f"缺少必需字段: {field}")
            
            if errors:
                return {"valid": False, "errors": errors}
            
            # 类型验证
            if not isinstance(data["user_id"], (int, str)):
                errors.append("user_id必须是整数或字符串")
            
            if not isinstance(data["username"], str) or len(data["username"]) < 3:
                errors.append("username必须是至少3个字符的字符串")
            
            if not isinstance(data["email"], str) or "@" not in data["email"]:
                errors.append("email格式无效")
            
            if not isinstance(data["age"], int) or data["age"] < 0 or data["age"] > 150:
                errors.append("age必须是0-150之间的整数")
            
            return {"valid": len(errors) == 0, "errors": errors}
        
        # 测试有效数据
        valid_data = {
            "user_id": 123,
            "username": "testuser",
            "email": "test@example.com",
            "age": 25
        }
        result = validate_user_data(valid_data)
        assert result["valid"]
        assert len(result["errors"]) == 0
        
        # 测试无效数据
        invalid_data_cases = [
            # 缺少字段
            {"user_id": 123, "username": "test"},
            # 类型错误
            {"user_id": 123, "username": "test", "email": "invalid", "age": "not_number"},
            # 值超出范围
            {"user_id": 123, "username": "ab", "email": "test@example.com", "age": -5},
        ]
        
        for invalid_data in invalid_data_cases:
            result = validate_user_data(invalid_data)
            assert not result["valid"]
            assert len(result["errors"]) > 0
    
    def test_file_processing_errors(self):
        """测试文件处理错误"""
        def safe_file_processor(file_path, max_size=1024*1024):
            """安全的文件处理器"""
            try:
                # 模拟文件大小检查
                import os
                if not os.path.exists(file_path):
                    return {"success": False, "error": "文件不存在", "error_code": "FILE_NOT_FOUND"}
                
                # 模拟文件大小检查
                file_size = len(file_path) * 1000  # 模拟文件大小
                if file_size > max_size:
                    return {
                        "success": False,
                        "error": f"文件过大: {file_size} > {max_size}",
                        "error_code": "FILE_TOO_LARGE"
                    }
                
                # 模拟文件内容处理
                if "corrupted" in file_path:
                    raise ValueError("文件内容损坏")
                
                return {"success": True, "data": {"processed": True, "size": file_size}}
                
            except PermissionError:
                return {"success": False, "error": "文件访问权限不足", "error_code": "PERMISSION_DENIED"}
            except ValueError as e:
                return {"success": False, "error": str(e), "error_code": "INVALID_FILE_CONTENT"}
            except Exception as e:
                return {"success": False, "error": f"文件处理错误: {str(e)}", "error_code": "FILE_PROCESSING_ERROR"}
        
        # 测试各种文件错误情况
        test_cases = [
            ("valid_file.txt", True, None),
            ("nonexistent.txt", False, "FILE_NOT_FOUND"),
            ("large_file.txt" * 1000, False, "FILE_TOO_LARGE"),
            ("corrupted_file.txt", False, "INVALID_FILE_CONTENT"),
        ]
        
        for file_path, expected_success, expected_error_code in test_cases:
            result = safe_file_processor(file_path)
            assert result["success"] == expected_success
            if not expected_success:
                assert result["error_code"] == expected_error_code


class TestResourceExhaustionHandling:
    """资源耗尽处理测试"""
    
    def test_memory_limit_handling(self):
        """测试内存限制处理"""
        def memory_intensive_operation(data_size, memory_limit=1024*1024):
            """内存密集型操作"""
            try:
                # 模拟内存使用检查
                estimated_memory = data_size * 8  # 假设每个元素8字节
                
                if estimated_memory > memory_limit:
                    return {
                        "success": False,
                        "error": f"操作需要内存 {estimated_memory} 超过限制 {memory_limit}",
                        "error_code": "MEMORY_LIMIT_EXCEEDED"
                    }
                
                # 模拟处理
                data = list(range(data_size))
                result = sum(data)
                
                return {"success": True, "result": result, "memory_used": estimated_memory}
                
            except MemoryError:
                return {"success": False, "error": "内存不足", "error_code": "OUT_OF_MEMORY"}
            except Exception as e:
                return {"success": False, "error": str(e), "error_code": "UNKNOWN"}
        
        # 测试正常操作
        result = memory_intensive_operation(1000)
        assert result["success"]
        
        # 测试内存限制
        result = memory_intensive_operation(200000, memory_limit=1024)
        assert not result["success"]
        assert result["error_code"] == "MEMORY_LIMIT_EXCEEDED"
    
    @pytest.mark.asyncio
    async def test_concurrent_request_limiting(self):
        """测试并发请求限制"""
        class ConcurrencyLimiter:
            def __init__(self, max_concurrent=5):
                self.max_concurrent = max_concurrent
                self.current_requests = 0
                self.lock = asyncio.Lock()
            
            async def process_request(self, request_id):
                """处理请求"""
                async with self.lock:
                    if self.current_requests >= self.max_concurrent:
                        return {
                            "success": False,
                            "error": "并发请求数超过限制",
                            "error_code": "CONCURRENCY_LIMIT_EXCEEDED",
                            "request_id": request_id
                        }
                    
                    self.current_requests += 1
                
                try:
                    # 模拟请求处理
                    await asyncio.sleep(0.1)
                    return {"success": True, "request_id": request_id}
                finally:
                    async with self.lock:
                        self.current_requests -= 1
        
        limiter = ConcurrencyLimiter(max_concurrent=3)
        
        # 创建多个并发请求
        tasks = [limiter.process_request(f"req_{i}") for i in range(10)]
        results = await asyncio.gather(*tasks)
        
        # 验证有些请求被限制
        successful_requests = [r for r in results if r["success"]]
        failed_requests = [r for r in results if not r["success"]]
        
        assert len(successful_requests) > 0
        assert len(failed_requests) > 0
        
        # 验证失败原因
        for failed_req in failed_requests:
            assert failed_req["error_code"] == "CONCURRENCY_LIMIT_EXCEEDED"
    
    def test_disk_space_handling(self):
        """测试磁盘空间处理"""
        def check_disk_space_and_write(file_size, available_space=1024*1024):
            """检查磁盘空间并写入文件"""
            try:
                if file_size > available_space:
                    return {
                        "success": False,
                        "error": f"磁盘空间不足: 需要 {file_size}, 可用 {available_space}",
                        "error_code": "INSUFFICIENT_DISK_SPACE"
                    }
                
                # 模拟文件写入
                return {"success": True, "bytes_written": file_size}
                
            except OSError as e:
                if "No space left on device" in str(e):
                    return {"success": False, "error": "磁盘空间已满", "error_code": "DISK_FULL"}
                else:
                    return {"success": False, "error": str(e), "error_code": "DISK_ERROR"}
        
        # 测试正常写入
        result = check_disk_space_and_write(1024, available_space=2048)
        assert result["success"]
        
        # 测试空间不足
        result = check_disk_space_and_write(2048, available_space=1024)
        assert not result["success"]
        assert result["error_code"] == "INSUFFICIENT_DISK_SPACE"


class TestServiceDependencyErrorHandling:
    """服务依赖错误处理测试"""
    
    @pytest.mark.asyncio
    async def test_database_connection_errors(self):
        """测试数据库连接错误处理"""
        class DatabaseService:
            def __init__(self, connection_pool=None):
                self.connection_pool = connection_pool
                self.retry_count = 0
                self.max_retries = 3
            
            async def execute_query(self, query):
                """执行数据库查询"""
                if not self.connection_pool:
                    return {
                        "success": False,
                        "error": "数据库连接池未初始化",
                        "error_code": "DB_POOL_NOT_INITIALIZED"
                    }
                
                for attempt in range(self.max_retries + 1):
                    try:
                        # 模拟数据库操作
                        if "SELECT" in query.upper():
                            if attempt < 2:  # 前两次失败
                                raise ConnectionError("数据库连接失败")
                            return {"success": True, "data": [{"id": 1, "name": "test"}]}
                        else:
                            return {"success": True, "affected_rows": 1}
                    
                    except ConnectionError as e:
                        if attempt < self.max_retries:
                            await asyncio.sleep(0.1 * (2 ** attempt))  # 指数退避
                            continue
                        return {
                            "success": False,
                            "error": f"数据库连接失败，已重试 {self.max_retries} 次",
                            "error_code": "DB_CONNECTION_FAILED"
                        }
                    except Exception as e:
                        return {
                            "success": False,
                            "error": f"数据库操作错误: {str(e)}",
                            "error_code": "DB_OPERATION_ERROR"
                        }
        
        # 测试无连接池
        db_service = DatabaseService()
        result = await db_service.execute_query("SELECT * FROM users")
        assert not result["success"]
        assert result["error_code"] == "DB_POOL_NOT_INITIALIZED"
        
        # 测试连接重试
        db_service = DatabaseService(connection_pool=Mock())
        result = await db_service.execute_query("SELECT * FROM users")
        assert result["success"]  # 第三次重试成功
    
    @pytest.mark.asyncio
    async def test_external_api_circuit_breaker(self):
        """测试外部API熔断器"""
        class CircuitBreaker:
            def __init__(self, failure_threshold=5, recovery_timeout=60):
                self.failure_threshold = failure_threshold
                self.recovery_timeout = recovery_timeout
                self.failure_count = 0
                self.last_failure_time = None
                self.state = "CLOSED"  # CLOSED, OPEN, HALF_OPEN
            
            async def call_external_api(self, api_endpoint):
                """调用外部API"""
                current_time = time.time()
                
                # 检查熔断器状态
                if self.state == "OPEN":
                    if current_time - self.last_failure_time < self.recovery_timeout:
                        return {
                            "success": False,
                            "error": "熔断器开启，拒绝请求",
                            "error_code": "CIRCUIT_BREAKER_OPEN"
                        }
                    else:
                        self.state = "HALF_OPEN"
                
                try:
                    # 模拟API调用
                    if "failing-api" in api_endpoint:
                        raise requests.exceptions.RequestException("API调用失败")
                    
                    # 成功调用
                    if self.state == "HALF_OPEN":
                        self.state = "CLOSED"
                        self.failure_count = 0
                    
                    return {"success": True, "data": {"status": "ok"}}
                
                except Exception as e:
                    self.failure_count += 1
                    self.last_failure_time = current_time
                    
                    if self.failure_count >= self.failure_threshold:
                        self.state = "OPEN"
                    
                    return {
                        "success": False,
                        "error": str(e),
                        "error_code": "EXTERNAL_API_ERROR",
                        "circuit_breaker_state": self.state
                    }
        
        circuit_breaker = CircuitBreaker(failure_threshold=3, recovery_timeout=1)
        
        # 模拟连续失败触发熔断
        for i in range(5):
            result = await circuit_breaker.call_external_api("https://failing-api.com/test")
            assert not result["success"]
        
        # 验证熔断器开启
        assert circuit_breaker.state == "OPEN"
        
        # 测试熔断器拒绝请求
        result = await circuit_breaker.call_external_api("https://good-api.com/test")
        assert not result["success"]
        assert result["error_code"] == "CIRCUIT_BREAKER_OPEN"
        
        # 等待恢复时间后测试半开状态
        await asyncio.sleep(1.1)
        result = await circuit_breaker.call_external_api("https://good-api.com/test")
        assert result["success"]
        assert circuit_breaker.state == "CLOSED"


class TestGracefulDegradation:
    """优雅降级测试"""
    
    def test_feature_fallback(self):
        """测试功能降级"""
        class FeatureService:
            def __init__(self):
                self.ai_service_available = True
                self.cache_available = True
                self.database_available = True
            
            def get_recommendation(self, user_id):
                """获取推荐内容"""
                try:
                    # 尝试AI推荐
                    if self.ai_service_available:
                        return {
                            "success": True,
                            "recommendations": ["AI推荐1", "AI推荐2", "AI推荐3"],
                            "source": "ai_service"
                        }
                except Exception:
                    self.ai_service_available = False
                
                try:
                    # 降级到缓存推荐
                    if self.cache_available:
                        return {
                            "success": True,
                            "recommendations": ["缓存推荐1", "缓存推荐2"],
                            "source": "cache",
                            "degraded": True
                        }
                except Exception:
                    self.cache_available = False
                
                try:
                    # 最终降级到默认推荐
                    if self.database_available:
                        return {
                            "success": True,
                            "recommendations": ["默认推荐1"],
                            "source": "default",
                            "degraded": True
                        }
                except Exception:
                    self.database_available = False
                
                # 完全失败
                return {
                    "success": False,
                    "error": "所有推荐服务不可用",
                    "error_code": "ALL_SERVICES_DOWN"
                }
        
        service = FeatureService()
        
        # 测试正常情况
        result = service.get_recommendation("user123")
        assert result["success"]
        assert result["source"] == "ai_service"
        assert "degraded" not in result
        
        # 测试AI服务不可用
        service.ai_service_available = False
        result = service.get_recommendation("user123")
        assert result["success"]
        assert result["source"] == "cache"
        assert result["degraded"]
        
        # 测试缓存也不可用
        service.cache_available = False
        result = service.get_recommendation("user123")
        assert result["success"]
        assert result["source"] == "default"
        assert result["degraded"]
        
        # 测试所有服务不可用
        service.database_available = False
        result = service.get_recommendation("user123")
        assert not result["success"]
        assert result["error_code"] == "ALL_SERVICES_DOWN"


if __name__ == "__main__":
    pytest.main([__file__, "-v", "--tb=short"])
